Workbook

Sheet Dados
A1: Lista de Ações
A2: =IFERROR(__xludf.DUMMYFUNCTION("GOOGLEFINANCE(B3,""name"")"),"Coca-Cola Co") -> Coca-Cola Co | C2: =IFERROR(__xludf.DUMMYFUNCTION("GOOGLEFINANCE(D3,""name"")"),"Microsoft Corp") -> Microsoft Corp | E2: =IFERROR(__xludf.DUMMYFUNCTION("GOOGLEFINANCE(F3,""name"")"),"Tesla Inc") -> Tesla Inc | G2: =IFERROR(__xludf.DUMMYFUNCTION("GOOGLEFINANCE(H3,""name"")"),"Apple Inc") -> Apple Inc | J2: Data Inicial | K2: 43831 | M2: Ref | N2: https://support.google.com/docs/answer/3093281?hl=pt-BR
A3: Código | B3: KO | C3: Código | D3: MSFT | E3: Código | F3: TSLA | G3: Código | H3: AAPL | J3: Data Final | K3: 44927
A4: =IFERROR(__xludf.DUMMYFUNCTION("GOOGLEFINANCE(B3,""price"",$K$2,$K$3)"),"Date") -> Date | B4: =IFERROR(__xludf.DUMMYFUNCTION("""COMPUTED_VALUE"""),"Close") -> Close | C4: =IFERROR(__xludf.DUMMYFUNCTION("GOOGLEFINANCE(D3,""price"",$K$2,$K$3)"),"Date") -> Date | D4: =IFERROR(__xludf.DUMMYFUNCTION("""COMPUTED_VALUE"""),"Close") -> Close | E4: =IFERROR(__xludf.DUMMYFUNCTION("GOOGLEFINANCE(F3,""price"",$K$2,$K$3)"),"Date") -> Date | F4: =IFERROR(__xludf.DUMMYFUNCTION("""COMPUTED_VALUE"""),"Close") -> Close | G4: =IFERROR(__xludf.DUMMYFUNCTION("GOOGLEFINANCE(H3,""price"",$K$2,$K$3)"),"Date") -> Date | H4: =IFERROR(__xludf.DUMMYFUNCTION("""COMPUTED_VALUE"""),"Close") -> Close
A5: =IFERROR(__xludf.DUMMYFUNCTION("""COMPUTED_VALUE"""),43832.66666666667) -> 43832.667 | B5: =IFERROR(__xludf.DUMMYFUNCTION("""COMPUTED_VALUE"""),54.99) -> 54.99 | C5: =IFERROR(__xludf.DUMMYFUNCTION("""COMPUTED_VALUE"""),43832.66666666667) -> 43832.667 | D5: =IFERROR(__xludf.DUMMYFUNCTION("""COMPUTED_VALUE"""),160.62) -> 160.62 | E5: =IFERROR(__xludf.DUMMYFUNCTION("""COMPUTED_VALUE"""),43832.66666666667) -> 43832.667 | F5: =IFERROR(__xludf.DUMMYFUNCTION("""COMPUTED_VALUE"""),28.68) -> 28.68 | G5: =IFERROR(__xludf.DUMMYFUNCTION("""COMPUTED_VALUE"""),43832.66666666667) -> 43832.667 | H5: =IFERROR(__xludf.DUMMYFUNCTION("""COMPUTED_VALUE"""),75.09) -> 75.09
A6: =IFERROR(__xludf.DUMMYFUNCTION("""COMPUTED_VALUE"""),43833.66666666667) -> 43833.667 | B6: =IFERROR(__xludf.DUMMYFUNCTION("""COMPUTED_VALUE"""),54.69) -> 54.69 | C6: =IFERROR(__xludf.DUMMYFUNCTION("""COMPUTED_VALUE"""),43833.66666666667) -> 43833.667 | D6: =IFERROR(__xludf.DUMMYFUNCTION("""COMPUTED_VALUE"""),158.62) -> 158.62 | E6: =IFERROR(__xludf.DUMMYFUNCTION("""COMPUTED_VALUE"""),43833.66666666667) -> 43833.667 | F6: =IFERROR(__xludf.DUMMYFUNCTION("""COMPUTED_VALUE"""),29.53) -> 29.53 | G6: =IFERROR(__xludf.DUMMYFUNCTION("""COMPUTED_VALUE"""),43833.66666666667) -> 43833.667 | H6: =IFERROR(__xludf.DUMMYFUNCTION("""COMPUTED_VALUE"""),74.36) -> 74.36
A7: =IFERROR(__xludf.DUMMYFUNCTION("""COMPUTED_VALUE"""),43836.66666666667) -> 43836.667 | B7: =IFERROR(__xludf.DUMMYFUNCTION("""COMPUTED_VALUE"""),54.67) -> 54.67 | C7: =IFERROR(__xludf.DUMMYFUNCTION("""COMPUTED_VALUE"""),43836.66666666667) -> 43836.667 | D7: =IFERROR(__xludf.DUMMYFUNCTION("""COMPUTED_VALUE"""),159.03) -> 159.03 | E7: =IFERROR(__xludf.DUMMYFUNCTION("""COMPUTED_VALUE"""),43836.66666666667) -> 43836.667 | F7: =IFERROR(__xludf.DUMMYFUNCTION("""COMPUTED_VALUE"""),30.1) -> 30.1 | G7: =IFERROR(__xludf.DUMMYFUNCTION("""COMPUTED_VALUE"""),43836.66666666667) -> 43836.667 | H7: =IFERROR(__xludf.DUMMYFUNCTION("""COMPUTED_VALUE"""),74.95) -> 74.95
A8: =IFERROR(__xludf.DUMMYFUNCTION("""COMPUTED_VALUE"""),43837.66666666667) -> 43837.667 | B8: =IFERROR(__xludf.DUMMYFUNCTION("""COMPUTED_VALUE"""),54.25) -> 54.25 | C8: =IFERROR(__xludf.DUMMYFUNCTION("""COMPUTED_VALUE"""),43837.66666666667) -> 43837.667 | D8: =IFERROR(__xludf.DUMMYFUNCTION("""COMPUTED_VALUE"""),157.58) -> 157.58 | E8: =IFERROR(__xludf.DUMMYFUNCTION("""COMPUTED_VALUE"""),43837.66666666667) -> 43837.667 | F8: =IFERROR(__xludf.DUMMYFUNCTION("""COMPUTED_VALUE"""),31.27) -> 31.27 | G8: =IFERROR(__xludf.DUMMYFUNCTION("""COMPUTED_VALUE"""),43837.66666666667) -> 43837.667 | H8: =IFERROR(__xludf.DUMMYFUNCTION("""COMPUTED_VALUE"""),74.6) -> 74.6
A9: =IFERROR(__xludf.DUMMYFUNCTION("""COMPUTED_VALUE"""),43838.66666666667) -> 43838.667 | B9: =IFERROR(__xludf.DUMMYFUNCTION("""COMPUTED_VALUE"""),54.35) -> 54.35 | C9: =IFERROR(__xludf.DUMMYFUNCTION("""COMPUTED_VALUE"""),43838.66666666667) -> 43838.667 | D9: =IFERROR(__xludf.DUMMYFUNCTION("""COMPUTED_VALUE"""),160.09) -> 160.09 | E9: =IFERROR(__xludf.DUMMYFUNCTION("""COMPUTED_VALUE"""),43838.66666666667) -> 43838.667 | F9: =IFERROR(__xludf.DUMMYFUNCTION("""COMPUTED_VALUE"""),32.81) -> 32.81 | G9: =IFERROR(__xludf.DUMMYFUNCTION("""COMPUTED_VALUE"""),43838.66666666667) -> 43838.667 | H9: =IFERROR(__xludf.DUMMYFUNCTION("""COMPUTED_VALUE"""),75.8) -> 75.8
A10: =IFERROR(__xludf.DUMMYFUNCTION("""COMPUTED_VALUE"""),43839.66666666667) -> 43839.667 | B10: =IFERROR(__xludf.DUMMYFUNCTION("""COMPUTED_VALUE"""),55.34) -> 55.34 | C10: =IFERROR(__xludf.DUMMYFUNCTION("""COMPUTED_VALUE"""),43839.66666666667) -> 43839.667 | D10: =IFERROR(__xludf.DUMMYFUNCTION("""COMPUTED_VALUE"""),162.09) -> 162.09 | E10: =IFERROR(__xludf.DUMMYFUNCTION("""COMPUTED_VALUE"""),43839.66666666667) -> 43839.667 | F10: =IFERROR(__xludf.DUMMYFUNCTION("""COMPUTED_VALUE"""),32.09) -> 32.09 | G10: =IFERROR(__xludf.DUMMYFUNCTION("""COMPUTED_VALUE"""),43839.66666666667) -> 43839.667 | H10: =IFERROR(__xludf.DUMMYFUNCTION("""COMPUTED_VALUE"""),77.41) -> 77.41
A11: =IFERROR(__xludf.DUMMYFUNCTION("""COMPUTED_VALUE"""),43840.66666666667) -> 43840.667 | B11: =IFERROR(__xludf.DUMMYFUNCTION("""COMPUTED_VALUE"""),55.53) -> 55.53 | C11: =IFERROR(__xludf.DUMMYFUNCTION("""COMPUTED_VALUE"""),43840.66666666667) -> 43840.667 | D11: =IFERROR(__xludf.DUMMYFUNCTION("""COMPUTED_VALUE"""),161.34) -> 161.34 | E11: =IFERROR(__xludf.DUMMYFUNCTION("""COMPUTED_VALUE"""),43840.66666666667) -> 43840.667 | F11: =IFERROR(__xludf.DUMMYFUNCTION("""COMPUTED_VALUE"""),31.88) -> 31.88 | G11: =IFERROR(__xludf.DUMMYFUNCTION("""COMPUTED_VALUE"""),43840.66666666667) -> 43840.667 | H11: =IFERROR(__xludf.DUMMYFUNCTION("""COMPUTED_VALUE"""),77.58) -> 77.58
A12: =IFERROR(__xludf.DUMMYFUNCTION("""COMPUTED_VALUE"""),43843.66666666667) -> 43843.667 | B12: =IFERROR(__xludf.DUMMYFUNCTION("""COMPUTED_VALUE"""),56.13) -> 56.13 | C12: =IFERROR(__xludf.DUMMYFUNCTION("""COMPUTED_VALUE"""),43843.66666666667) -> 43843.667 | D12: =IFERROR(__xludf.DUMMYFUNCTION("""COMPUTED_VALUE"""),163.28) -> 163.28 | E12: =IFERROR(__xludf.DUMMYFUNCTION("""COMPUTED_VALUE"""),43843.66666666667) -> 43843.667 | F12: =IFERROR(__xludf.DUMMYFUNCTION("""COMPUTED_VALUE"""),34.99) -> 34.99 | G12: =IFERROR(__xludf.DUMMYFUNCTION("""COMPUTED_VALUE"""),43843.66666666667) -> 43843.667 | H12: =IFERROR(__xludf.DUMMYFUNCTION("""COMPUTED_VALUE"""),79.24) -> 79.24
A13: =IFERROR(__xludf.DUMMYFUNCTION("""COMPUTED_VALUE"""),43844.66666666667) -> 43844.667 | B13: =IFERROR(__xludf.DUMMYFUNCTION("""COMPUTED_VALUE"""),56.0) -> 56 | C13: =IFERROR(__xludf.DUMMYFUNCTION("""COMPUTED_VALUE"""),43844.66666666667) -> 43844.667 | D13: =IFERROR(__xludf.DUMMYFUNCTION("""COMPUTED_VALUE"""),162.13) -> 162.13 | E13: =IFERROR(__xludf.DUMMYFUNCTION("""COMPUTED_VALUE"""),43844.66666666667) -> 43844.667 | F13: =IFERROR(__xludf.DUMMYFUNCTION("""COMPUTED_VALUE"""),35.86) -> 35.86 | G13: =IFERROR(__xludf.DUMMYFUNCTION("""COMPUTED_VALUE"""),43844.66666666667) -> 43844.667 | H13: =IFERROR(__xludf.DUMMYFUNCTION("""COMPUTED_VALUE"""),78.17) -> 78.17
A14: =IFERROR(__xludf.DUMMYFUNCTION("""COMPUTED_VALUE"""),43845.66666666667) -> 43845.667 | B14: =IFERROR(__xludf.DUMMYFUNCTION("""COMPUTED_VALUE"""),56.7) -> 56.7 | C14: =IFERROR(__xludf.DUMMYFUNCTION("""COMPUTED_VALUE"""),43845.66666666667) -> 43845.667 | D14: =IFERROR(__xludf.DUMMYFUNCTION("""COMPUTED_VALUE"""),163.18) -> 163.18 | E14: =IFERROR(__xludf.DUMMYFUNCTION("""COMPUTED_VALUE"""),43845.66666666667) -> 43845.667 | F14: =IFERROR(__xludf.DUMMYFUNCTION("""COMPUTED_VALUE"""),34.57) -> 34.57 | G14: =IFERROR(__xludf.DUMMYFUNCTION("""COMPUTED_VALUE"""),43845.66666666667) -> 43845.667 | H14: =IFERROR(__xludf.DUMMYFUNCTION("""COMPUTED_VALUE"""),77.83) -> 77.83
A15: =IFERROR(__xludf.DUMMYFUNCTION("""COMPUTED_VALUE"""),43846.66666666667) -> 43846.667 | B15: =IFERROR(__xludf.DUMMYFUNCTION("""COMPUTED_VALUE"""),56.82) -> 56.82 | C15: =IFERROR(__xludf.DUMMYFUNCTION("""COMPUTED_VALUE"""),43846.66666666667) -> 43846.667 | D15: =IFERROR(__xludf.DUMMYFUNCTION("""COMPUTED_VALUE"""),166.17) -> 166.17 | E15: =IFERROR(__xludf.DUMMYFUNCTION("""COMPUTED_VALUE"""),43846.66666666667) -> 43846.667 | F15: =IFERROR(__xludf.DUMMYFUNCTION("""COMPUTED_VALUE"""),34.23) -> 34.23 | G15: =IFERROR(__xludf.DUMMYFUNCTION("""COMPUTED_VALUE"""),43846.66666666667) -> 43846.667 | H15: =IFERROR(__xludf.DUMMYFUNCTION("""COMPUTED_VALUE"""),78.81) -> 78.81
A16: =IFERROR(__xludf.DUMMYFUNCTION("""COMPUTED_VALUE"""),43847.66666666667) -> 43847.667 | B16: =IFERROR(__xludf.DUMMYFUNCTION("""COMPUTED_VALUE"""),56.94) -> 56.94 | C16: =IFERROR(__xludf.DUMMYFUNCTION("""COMPUTED_VALUE"""),43847.66666666667) -> 43847.667 | D16: =IFERROR(__xludf.DUMMYFUNCTION("""COMPUTED_VALUE"""),167.1) -> 167.1 | E16: =IFERROR(__xludf.DUMMYFUNCTION("""COMPUTED_VALUE"""),43847.66666666667) -> 43847.667 | F16: =IFERROR(__xludf.DUMMYFUNCTION("""COMPUTED_VALUE"""),34.03) -> 34.03 | G16: =IFERROR(__xludf.DUMMYFUNCTION("""COMPUTED_VALUE"""),43847.66666666667) -> 43847.667 | H16: =IFERROR(__xludf.DUMMYFUNCTION("""COMPUTED_VALUE"""),79.68) -> 79.68
A17: =IFERROR(__xludf.DUMMYFUNCTION("""COMPUTED_VALUE"""),43851.66666666667) -> 43851.667 | B17: =IFERROR(__xludf.DUMMYFUNCTION("""COMPUTED_VALUE"""),57.17) -> 57.17 | C17: =IFERROR(__xludf.DUMMYFUNCTION("""COMPUTED_VALUE"""),43851.66666666667) -> 43851.667 | D17: =IFERROR(__xludf.DUMMYFUNCTION("""COMPUTED_VALUE"""),166.5) -> 166.5 | E17: =IFERROR(__xludf.DUMMYFUNCTION("""COMPUTED_VALUE"""),43851.66666666667) -> 43851.667 | F17: =IFERROR(__xludf.DUMMYFUNCTION("""COMPUTED_VALUE"""),36.48) -> 36.48 | G17: =IFERROR(__xludf.DUMMYFUNCTION("""COMPUTED_VALUE"""),43851.66666666667) -> 43851.667 | H17: =IFERROR(__xludf.DUMMYFUNCTION("""COMPUTED_VALUE"""),79.14) -> 79.14
A18: =IFERROR(__xludf.DUMMYFUNCTION("""COMPUTED_VALUE"""),43852.66666666667) -> 43852.667 | B18: =IFERROR(__xludf.DUMMYFUNCTION("""COMPUTED_VALUE"""),57.61) -> 57.61 | C18: =IFERROR(__xludf.DUMMYFUNCTION("""COMPUTED_VALUE"""),43852.66666666667) -> 43852.667 | D18: =IFERROR(__xludf.DUMMYFUNCTION("""COMPUTED_VALUE"""),165.7) -> 165.7 | E18: =IFERROR(__xludf.DUMMYFUNCTION("""COMPUTED_VALUE"""),43852.66666666667) -> 43852.667 | F18: =IFERROR(__xludf.DUMMYFUNCTION("""COMPUTED_VALUE"""),37.97) -> 37.97 | G18: =IFERROR(__xludf.DUMMYFUNCTION("""COMPUTED_VALUE"""),43852.66666666667) -> 43852.667 | H18: =IFERROR(__xludf.DUMMYFUNCTION("""COMPUTED_VALUE"""),79.43) -> 79.43
A19: =IFERROR(__xludf.DUMMYFUNCTION("""COMPUTED_VALUE"""),43853.66666666667) -> 43853.667 | B19: =IFERROR(__xludf.DUMMYFUNCTION("""COMPUTED_VALUE"""),57.83) -> 57.83 | C19: =IFERROR(__xludf.DUMMYFUNCTION("""COMPUTED_VALUE"""),43853.66666666667) -> 43853.667 | D19: =IFERROR(__xludf.DUMMYFUNCTION("""COMPUTED_VALUE"""),166.72) -> 166.72 | E19: =IFERROR(__xludf.DUMMYFUNCTION("""COMPUTED_VALUE"""),43853.66666666667) -> 43853.667 | F19: =IFERROR(__xludf.DUMMYFUNCTION("""COMPUTED_VALUE"""),38.15) -> 38.15 | G19: =IFERROR(__xludf.DUMMYFUNCTION("""COMPUTED_VALUE"""),43853.66666666667) -> 43853.667 | H19: =IFERROR(__xludf.DUMMYFUNCTION("""COMPUTED_VALUE"""),79.81) -> 79.81
A20: =IFERROR(__xludf.DUMMYFUNCTION("""COMPUTED_VALUE"""),43854.66666666667) -> 43854.667 | B20: =IFERROR(__xludf.DUMMYFUNCTION("""COMPUTED_VALUE"""),57.68) -> 57.68 | C20: =IFERROR(__xludf.DUMMYFUNCTION("""COMPUTED_VALUE"""),43854.66666666667) -> 43854.667 | D20: =IFERROR(__xludf.DUMMYFUNCTION("""COMPUTED_VALUE"""),165.04) -> 165.04 | E20: =IFERROR(__xludf.DUMMYFUNCTION("""COMPUTED_VALUE"""),43854.66666666667) -> 43854.667 | F20: =IFERROR(__xludf.DUMMYFUNCTION("""COMPUTED_VALUE"""),37.65) -> 37.65 | G20: =IFERROR(__xludf.DUMMYFUNCTION("""COMPUTED_VALUE"""),43854.66666666667) -> 43854.667 | H20: =IFERROR(__xludf.DUMMYFUNCTION("""COMPUTED_VALUE"""),79.58) -> 79.58
A21: =IFERROR(__xludf.DUMMYFUNCTION("""COMPUTED_VALUE"""),43857.66666666667) -> 43857.667 | B21: =IFERROR(__xludf.DUMMYFUNCTION("""COMPUTED_VALUE"""),57.48) -> 57.48 | C21: =IFERROR(__xludf.DUMMYFUNCTION("""COMPUTED_VALUE"""),43857.66666666667) -> 43857.667 | D21: =IFERROR(__xludf.DUMMYFUNCTION("""COMPUTED_VALUE"""),162.28) -> 162.28 | E21: =IFERROR(__xludf.DUMMYFUNCTION("""COMPUTED_VALUE"""),43857.66666666667) -> 43857.667 | F21: =IFERROR(__xludf.DUMMYFUNCTION("""COMPUTED_VALUE"""),37.2) -> 37.2 | G21: =IFERROR(__xludf.DUMMYFUNCTION("""COMPUTED_VALUE"""),43857.66666666667) -> 43857.667 | H21: =IFERROR(__xludf.DUMMYFUNCTION("""COMPUTED_VALUE"""),77.24) -> 77.24
A22: =IFERROR(__xludf.DUMMYFUNCTION("""COMPUTED_VALUE"""),43858.66666666667) -> 43858.667 | B22: =IFERROR(__xludf.DUMMYFUNCTION("""COMPUTED_VALUE"""),57.01) -> 57.01 | C22: =IFERROR(__xludf.DUMMYFUNCTION("""COMPUTED_VALUE"""),43858.66666666667) -> 43858.667 | D22: =IFERROR(__xludf.DUMMYFUNCTION("""COMPUTED_VALUE"""),165.46) -> 165.46 | E22: =IFERROR(__xludf.DUMMYFUNCTION("""COMPUTED_VALUE"""),43858.66666666667) -> 43858.667 | F22: =IFERROR(__xludf.DUMMYFUNCTION("""COMPUTED_VALUE"""),37.79) -> 37.79 | G22: =IFERROR(__xludf.DUMMYFUNCTION("""COMPUTED_VALUE"""),43858.66666666667) -> 43858.667 | H22: =IFERROR(__xludf.DUMMYFUNCTION("""COMPUTED_VALUE"""),79.42) -> 79.42
A23: =IFERROR(__xludf.DUMMYFUNCTION("""COMPUTED_VALUE"""),43859.66666666667) -> 43859.667 | B23: =IFERROR(__xludf.DUMMYFUNCTION("""COMPUTED_VALUE"""),57.01) -> 57.01 | C23: =IFERROR(__xludf.DUMMYFUNCTION("""COMPUTED_VALUE"""),43859.66666666667) -> 43859.667 | D23: =IFERROR(__xludf.DUMMYFUNCTION("""COMPUTED_VALUE"""),168.04) -> 168.04 | E23: =IFERROR(__xludf.DUMMYFUNCTION("""COMPUTED_VALUE"""),43859.66666666667) -> 43859.667 | F23: =IFERROR(__xludf.DUMMYFUNCTION("""COMPUTED_VALUE"""),38.73) -> 38.73 | G23: =IFERROR(__xludf.DUMMYFUNCTION("""COMPUTED_VALUE"""),43859.66666666667) -> 43859.667 | H23: =IFERROR(__xludf.DUMMYFUNCTION("""COMPUTED_VALUE"""),81.08) -> 81.08
A24: =IFERROR(__xludf.DUMMYFUNCTION("""COMPUTED_VALUE"""),43860.66666666667) -> 43860.667 | B24: =IFERROR(__xludf.DUMMYFUNCTION("""COMPUTED_VALUE"""),58.86) -> 58.86 | C24: =IFERROR(__xludf.DUMMYFUNCTION("""COMPUTED_VALUE"""),43860.66666666667) -> 43860.667 | D24: =IFERROR(__xludf.DUMMYFUNCTION("""COMPUTED_VALUE"""),172.78) -> 172.78 | E24: =IFERROR(__xludf.DUMMYFUNCTION("""COMPUTED_VALUE"""),43860.66666666667) -> 43860.667 | F24: =IFERROR(__xludf.DUMMYFUNCTION("""COMPUTED_VALUE"""),42.72) -> 42.72 | G24: =IFERROR(__xludf.DUMMYFUNCTION("""COMPUTED_VALUE"""),43860.66666666667) -> 43860.667 | H24: =IFERROR(__xludf.DUMMYFUNCTION("""COMPUTED_VALUE"""),80.97) -> 80.97
A25: =IFERROR(__xludf.DUMMYFUNCTION("""COMPUTED_VALUE"""),43861.66666666667) -> 43861.667 | B25: =IFERROR(__xludf.DUMMYFUNCTION("""COMPUTED_VALUE"""),58.4) -> 58.4 | C25: =IFERROR(__xludf.DUMMYFUNCTION("""COMPUTED_VALUE"""),43861.66666666667) -> 43861.667 | D25: =IFERROR(__xludf.DUMMYFUNCTION("""COMPUTED_VALUE"""),170.23) -> 170.23 | E25: =IFERROR(__xludf.DUMMYFUNCTION("""COMPUTED_VALUE"""),43861.66666666667) -> 43861.667 | F25: =IFERROR(__xludf.DUMMYFUNCTION("""COMPUTED_VALUE"""),43.37) -> 43.37 | G25: =IFERROR(__xludf.DUMMYFUNCTION("""COMPUTED_VALUE"""),43861.66666666667) -> 43861.667 | H25: =IFERROR(__xludf.DUMMYFUNCTION("""COMPUTED_VALUE"""),77.38) -> 77.38
A26: =IFERROR(__xludf.DUMMYFUNCTION("""COMPUTED_VALUE"""),43864.66666666667) -> 43864.667 | B26: =IFERROR(__xludf.DUMMYFUNCTION("""COMPUTED_VALUE"""),58.58) -> 58.58 | C26: =IFERROR(__xludf.DUMMYFUNCTION("""COMPUTED_VALUE"""),43864.66666666667) -> 43864.667 | D26: =IFERROR(__xludf.DUMMYFUNCTION("""COMPUTED_VALUE"""),174.38) -> 174.38 | E26: =IFERROR(__xludf.DUMMYFUNCTION("""COMPUTED_VALUE"""),43864.66666666667) -> 43864.667 | F26: =IFERROR(__xludf.DUMMYFUNCTION("""COMPUTED_VALUE"""),52.0) -> 52 | G26: =IFERROR(__xludf.DUMMYFUNCTION("""COMPUTED_VALUE"""),43864.66666666667) -> 43864.667 | H26: =IFERROR(__xludf.DUMMYFUNCTION("""COMPUTED_VALUE"""),77.17) -> 77.17
A27: =IFERROR(__xludf.DUMMYFUNCTION("""COMPUTED_VALUE"""),43865.66666666667) -> 43865.667 | B27: =IFERROR(__xludf.DUMMYFUNCTION("""COMPUTED_VALUE"""),58.84) -> 58.84 | C27: =IFERROR(__xludf.DUMMYFUNCTION("""COMPUTED_VALUE"""),43865.66666666667) -> 43865.667 | D27: =IFERROR(__xludf.DUMMYFUNCTION("""COMPUTED_VALUE"""),180.12) -> 180.12 | E27: =IFERROR(__xludf.DUMMYFUNCTION("""COMPUTED_VALUE"""),43865.66666666667) -> 43865.667 | F27: =IFERROR(__xludf.DUMMYFUNCTION("""COMPUTED_VALUE"""),59.14) -> 59.14 | G27: =IFERROR(__xludf.DUMMYFUNCTION("""COMPUTED_VALUE"""),43865.66666666667) -> 43865.667 | H27: =IFERROR(__xludf.DUMMYFUNCTION("""COMPUTED_VALUE"""),79.71) -> 79.71
A28: =IFERROR(__xludf.DUMMYFUNCTION("""COMPUTED_VALUE"""),43866.66666666667) -> 43866.667 | B28: =IFERROR(__xludf.DUMMYFUNCTION("""COMPUTED_VALUE"""),58.85) -> 58.85 | C28: =IFERROR(__xludf.DUMMYFUNCTION("""COMPUTED_VALUE"""),43866.66666666667) -> 43866.667 | D28: =IFERROR(__xludf.DUMMYFUNCTION("""COMPUTED_VALUE"""),179.9) -> 179.9 | E28: =IFERROR(__xludf.DUMMYFUNCTION("""COMPUTED_VALUE"""),43866.66666666667) -> 43866.667 | F28: =IFERROR(__xludf.DUMMYFUNCTION("""COMPUTED_VALUE"""),48.98) -> 48.98 | G28: =IFERROR(__xludf.DUMMYFUNCTION("""COMPUTED_VALUE"""),43866.66666666667) -> 43866.667 | H28: =IFERROR(__xludf.DUMMYFUNCTION("""COMPUTED_VALUE"""),80.36) -> 80.36
A29: =IFERROR(__xludf.DUMMYFUNCTION("""COMPUTED_VALUE"""),43867.66666666667) -> 43867.667 | B29: =IFERROR(__xludf.DUMMYFUNCTION("""COMPUTED_VALUE"""),58.99) -> 58.99 | C29: =IFERROR(__xludf.DUMMYFUNCTION("""COMPUTED_VALUE"""),43867.66666666667) -> 43867.667 | D29: =IFERROR(__xludf.DUMMYFUNCTION("""COMPUTED_VALUE"""),183.63) -> 183.63 | E29: =IFERROR(__xludf.DUMMYFUNCTION("""COMPUTED_VALUE"""),43867.66666666667) -> 43867.667 | F29: =IFERROR(__xludf.DUMMYFUNCTION("""COMPUTED_VALUE"""),49.93) -> 49.93 | G29: =IFERROR(__xludf.DUMMYFUNCTION("""COMPUTED_VALUE"""),43867.66666666667) -> 43867.667 | H29: =IFERROR(__xludf.DUMMYFUNCTION("""COMPUTED_VALUE"""),81.3) -> 81.3
A30: =IFERROR(__xludf.DUMMYFUNCTION("""COMPUTED_VALUE"""),43868.66666666667) -> 43868.667 | B30: =IFERROR(__xludf.DUMMYFUNCTION("""COMPUTED_VALUE"""),59.19) -> 59.19 | C30: =IFERROR(__xludf.DUMMYFUNCTION("""COMPUTED_VALUE"""),43868.66666666667) -> 43868.667 | D30: =IFERROR(__xludf.DUMMYFUNCTION("""COMPUTED_VALUE"""),183.89) -> 183.89 | E30: =IFERROR(__xludf.DUMMYFUNCTION("""COMPUTED_VALUE"""),43868.66666666667) -> 43868.667 | F30: =IFERROR(__xludf.DUMMYFUNCTION("""COMPUTED_VALUE"""),49.87) -> 49.87 | G30: =IFERROR(__xludf.DUMMYFUNCTION("""COMPUTED_VALUE"""),43868.66666666667) -> 43868.667 | H30: =IFERROR(__xludf.DUMMYFUNCTION("""COMPUTED_VALUE"""),80.01) -> 80.01
A31: =IFERROR(__xludf.DUMMYFUNCTION("""COMPUTED_VALUE"""),43871.66666666667) -> 43871.667 | B31: =IFERROR(__xludf.DUMMYFUNCTION("""COMPUTED_VALUE"""),59.75) -> 59.75 | C31: =IFERROR(__xludf.DUMMYFUNCTION("""COMPUTED_VALUE"""),43871.66666666667) -> 43871.667 | D31: =IFERROR(__xludf.DUMMYFUNCTION("""COMPUTED_VALUE"""),188.7) -> 188.7 | E31: =IFERROR(__xludf.DUMMYFUNCTION("""COMPUTED_VALUE"""),43871.66666666667) -> 43871.667 | F31: =IFERROR(__xludf.DUMMYFUNCTION("""COMPUTED_VALUE"""),51.42) -> 51.42 | G31: =IFERROR(__xludf.DUMMYFUNCTION("""COMPUTED_VALUE"""),43871.66666666667) -> 43871.667 | H31: =IFERROR(__xludf.DUMMYFUNCTION("""COMPUTED_VALUE"""),80.39) -> 80.39
A32: =IFERROR(__xludf.DUMMYFUNCTION("""COMPUTED_VALUE"""),43872.66666666667) -> 43872.667 | B32: =IFERROR(__xludf.DUMMYFUNCTION("""COMPUTED_VALUE"""),59.59) -> 59.59 | C32: =IFERROR(__xludf.DUMMYFUNCTION("""COMPUTED_VALUE"""),43872.66666666667) -> 43872.667 | D32: =IFERROR(__xludf.DUMMYFUNCTION("""COMPUTED_VALUE"""),184.44) -> 184.44 | E32: =IFERROR(__xludf.DUMMYFUNCTION("""COMPUTED_VALUE"""),43872.66666666667) -> 43872.667 | F32: =IFERROR(__xludf.DUMMYFUNCTION("""COMPUTED_VALUE"""),51.63) -> 51.63 | G32: =IFERROR(__xludf.DUMMYFUNCTION("""COMPUTED_VALUE"""),43872.66666666667) -> 43872.667 | H32: =IFERROR(__xludf.DUMMYFUNCTION("""COMPUTED_VALUE"""),79.9) -> 79.9
A33: =IFERROR(__xludf.DUMMYFUNCTION("""COMPUTED_VALUE"""),43873.66666666667) -> 43873.667 | B33: =IFERROR(__xludf.DUMMYFUNCTION("""COMPUTED_VALUE"""),59.41) -> 59.41 | C33: =IFERROR(__xludf.DUMMYFUNCTION("""COMPUTED_VALUE"""),43873.66666666667) -> 43873.667 | D33: =IFERROR(__xludf.DUMMYFUNCTION("""COMPUTED_VALUE"""),184.71) -> 184.71 | E33: =IFERROR(__xludf.DUMMYFUNCTION("""COMPUTED_VALUE"""),43873.66666666667) -> 43873.667 | F33: =IFERROR(__xludf.DUMMYFUNCTION("""COMPUTED_VALUE"""),51.15) -> 51.15 | G33: =IFERROR(__xludf.DUMMYFUNCTION("""COMPUTED_VALUE"""),43873.66666666667) -> 43873.667 | H33: =IFERROR(__xludf.DUMMYFUNCTION("""COMPUTED_VALUE"""),81.8) -> 81.8
A34: =IFERROR(__xludf.DUMMYFUNCTION("""COMPUTED_VALUE"""),43874.66666666667) -> 43874.667 | B34: =IFERROR(__xludf.DUMMYFUNCTION("""COMPUTED_VALUE"""),59.61) -> 59.61 | C34: =IFERROR(__xludf.DUMMYFUNCTION("""COMPUTED_VALUE"""),43874.66666666667) -> 43874.667 | D34: =IFERROR(__xludf.DUMMYFUNCTION("""COMPUTED_VALUE"""),183.71) -> 183.71 | E34: =IFERROR(__xludf.DUMMYFUNCTION("""COMPUTED_VALUE"""),43874.66666666667) -> 43874.667 | F34: =IFERROR(__xludf.DUMMYFUNCTION("""COMPUTED_VALUE"""),53.6) -> 53.6 | G34: =IFERROR(__xludf.DUMMYFUNCTION("""COMPUTED_VALUE"""),43874.66666666667) -> 43874.667 | H34: =IFERROR(__xludf.DUMMYFUNCTION("""COMPUTED_VALUE"""),81.22) -> 81.22
A35: =IFERROR(__xludf.DUMMYFUNCTION("""COMPUTED_VALUE"""),43875.66666666667) -> 43875.667 | B35: =IFERROR(__xludf.DUMMYFUNCTION("""COMPUTED_VALUE"""),59.95) -> 59.95 | C35: =IFERROR(__xludf.DUMMYFUNCTION("""COMPUTED_VALUE"""),43875.66666666667) -> 43875.667 | D35: =IFERROR(__xludf.DUMMYFUNCTION("""COMPUTED_VALUE"""),185.35) -> 185.35 | E35: =IFERROR(__xludf.DUMMYFUNCTION("""COMPUTED_VALUE"""),43875.66666666667) -> 43875.667 | F35: =IFERROR(__xludf.DUMMYFUNCTION("""COMPUTED_VALUE"""),53.34) -> 53.34 | G35: =IFERROR(__xludf.DUMMYFUNCTION("""COMPUTED_VALUE"""),43875.66666666667) -> 43875.667 | H35: =IFERROR(__xludf.DUMMYFUNCTION("""COMPUTED_VALUE"""),81.24) -> 81.24
A36: =IFERROR(__xludf.DUMMYFUNCTION("""COMPUTED_VALUE"""),43879.66666666667) -> 43879.667 | B36: =IFERROR(__xludf.DUMMYFUNCTION("""COMPUTED_VALUE"""),59.53) -> 59.53 | C36: =IFERROR(__xludf.DUMMYFUNCTION("""COMPUTED_VALUE"""),43879.66666666667) -> 43879.667 | D36: =IFERROR(__xludf.DUMMYFUNCTION("""COMPUTED_VALUE"""),187.23) -> 187.23 | E36: =IFERROR(__xludf.DUMMYFUNCTION("""COMPUTED_VALUE"""),43879.66666666667) -> 43879.667 | F36: =IFERROR(__xludf.DUMMYFUNCTION("""COMPUTED_VALUE"""),57.23) -> 57.23 | G36: =IFERROR(__xludf.DUMMYFUNCTION("""COMPUTED_VALUE"""),43879.66666666667) -> 43879.667 | H36: =IFERROR(__xludf.DUMMYFUNCTION("""COMPUTED_VALUE"""),79.75) -> 79.75
A37: =IFERROR(__xludf.DUMMYFUNCTION("""COMPUTED_VALUE"""),43880.66666666667) -> 43880.667 | B37: =IFERROR(__xludf.DUMMYFUNCTION("""COMPUTED_VALUE"""),59.77) -> 59.77 | C37: =IFERROR(__xludf.DUMMYFUNCTION("""COMPUTED_VALUE"""),43880.66666666667) -> 43880.667 | D37: =IFERROR(__xludf.DUMMYFUNCTION("""COMPUTED_VALUE"""),187.28) -> 187.28 | E37: =IFERROR(__xludf.DUMMYFUNCTION("""COMPUTED_VALUE"""),43880.66666666667) -> 43880.667 | F37: =IFERROR(__xludf.DUMMYFUNCTION("""COMPUTED_VALUE"""),61.16) -> 61.16 | G37: =IFERROR(__xludf.DUMMYFUNCTION("""COMPUTED_VALUE"""),43880.66666666667) -> 43880.667 | H37: =IFERROR(__xludf.DUMMYFUNCTION("""COMPUTED_VALUE"""),80.91) -> 80.91
A38: =IFERROR(__xludf.DUMMYFUNCTION("""COMPUTED_VALUE"""),43881.66666666667) -> 43881.667 | B38: =IFERROR(__xludf.DUMMYFUNCTION("""COMPUTED_VALUE"""),59.72) -> 59.72 | C38: =IFERROR(__xludf.DUMMYFUNCTION("""COMPUTED_VALUE"""),43881.66666666667) -> 43881.667 | D38: =IFERROR(__xludf.DUMMYFUNCTION("""COMPUTED_VALUE"""),184.42) -> 184.42 | E38: =IFERROR(__xludf.DUMMYFUNCTION("""COMPUTED_VALUE"""),43881.66666666667) -> 43881.667 | F38: =IFERROR(__xludf.DUMMYFUNCTION("""COMPUTED_VALUE"""),59.96) -> 59.96 | G38: =IFERROR(__xludf.DUMMYFUNCTION("""COMPUTED_VALUE"""),43881.66666666667) -> 43881.667 | H38: =IFERROR(__xludf.DUMMYFUNCTION("""COMPUTED_VALUE"""),80.08) -> 80.08
A39: =IFERROR(__xludf.DUMMYFUNCTION("""COMPUTED_VALUE"""),43882.66666666667) -> 43882.667 | B39: =IFERROR(__xludf.DUMMYFUNCTION("""COMPUTED_VALUE"""),60.13) -> 60.13 | C39: =IFERROR(__xludf.DUMMYFUNCTION("""COMPUTED_VALUE"""),43882.66666666667) -> 43882.667 | D39: =IFERROR(__xludf.DUMMYFUNCTION("""COMPUTED_VALUE"""),178.59) -> 178.59 | E39: =IFERROR(__xludf.DUMMYFUNCTION("""COMPUTED_VALUE"""),43882.66666666667) -> 43882.667 | F39: =IFERROR(__xludf.DUMMYFUNCTION("""COMPUTED_VALUE"""),60.07) -> 60.07 | G39: =IFERROR(__xludf.DUMMYFUNCTION("""COMPUTED_VALUE"""),43882.66666666667) -> 43882.667 | H39: =IFERROR(__xludf.DUMMYFUNCTION("""COMPUTED_VALUE"""),78.26) -> 78.26
A40: =IFERROR(__xludf.DUMMYFUNCTION("""COMPUTED_VALUE"""),43885.66666666667) -> 43885.667 | B40: =IFERROR(__xludf.DUMMYFUNCTION("""COMPUTED_VALUE"""),58.65) -> 58.65 | C40: =IFERROR(__xludf.DUMMYFUNCTION("""COMPUTED_VALUE"""),43885.66666666667) -> 43885.667 | D40: =IFERROR(__xludf.DUMMYFUNCTION("""COMPUTED_VALUE"""),170.89) -> 170.89 | E40: =IFERROR(__xludf.DUMMYFUNCTION("""COMPUTED_VALUE"""),43885.66666666667) -> 43885.667 | F40: =IFERROR(__xludf.DUMMYFUNCTION("""COMPUTED_VALUE"""),55.59) -> 55.59 | G40: =IFERROR(__xludf.DUMMYFUNCTION("""COMPUTED_VALUE"""),43885.66666666667) -> 43885.667 | H40: =IFERROR(__xludf.DUMMYFUNCTION("""COMPUTED_VALUE"""),74.55) -> 74.55
...

Sheet Atributos
A1: Atributos Ações
A2: Código | B2: name | C2: price | D2: priceopen | E2: high | F2: low | G2: volume | H2: marketcap | I2: tradetime | J2: datadelay | K2: volumeavg | L2: pe | M2: eps | N2: high52 | O2: low52 | P2: change | Q2: beta | R2: changepct | S2: closeyest | T2: shares | U2: currency
A3: KO | B3: =IFERROR(__xludf.DUMMYFUNCTION("GOOGLEFINANCE($A$3,B2)"),"Coca-Cola Co") -> Coca-Cola Co | C3: =IFERROR(__xludf.DUMMYFUNCTION("GOOGLEFINANCE($A$3,C2)"),80.03) -> 80.03 | D3: =IFERROR(__xludf.DUMMYFUNCTION("GOOGLEFINANCE($A$3,D2)"),79.0) -> 79 | E3: =IFERROR(__xludf.DUMMYFUNCTION("GOOGLEFINANCE($A$3,E2)"),80.32) -> 80.32 | F3: =IFERROR(__xludf.DUMMYFUNCTION("GOOGLEFINANCE($A$3,F2)"),78.28) -> 78.28 | G3: =IFERROR(__xludf.DUMMYFUNCTION("GOOGLEFINANCE($A$3,G2)"),1.98831E7) -> 19883100 | H3: =IFERROR(__xludf.DUMMYFUNCTION("GOOGLEFINANCE($A$3,H2)"),3.44327629207E11) -> 344327629207 | I3: =IFERROR(__xludf.DUMMYFUNCTION("GOOGLEFINANCE($A$3,I2)"),46154.666712962964) -> 46154.667 | J3: =IFERROR(__xludf.DUMMYFUNCTION("GOOGLEFINANCE($A$3,J2)"),0.0) -> 0 | K3: =IFERROR(__xludf.DUMMYFUNCTION("GOOGLEFINANCE($A$3,K2)"),1.4002122E7) -> 14002122 | L3: =IFERROR(__xludf.DUMMYFUNCTION("GOOGLEFINANCE($A$3,L2)"),25.2) -> 25.2 | M3: =IFERROR(__xludf.DUMMYFUNCTION("GOOGLEFINANCE($A$3,M2)"),3.18) -> 3.18 | N3: =IFERROR(__xludf.DUMMYFUNCTION("GOOGLEFINANCE($A$3,N2)"),82.0) -> 82 | O3: =IFERROR(__xludf.DUMMYFUNCTION("GOOGLEFINANCE($A$3,O2)"),65.35) -> 65.35 | P3: =IFERROR(__xludf.DUMMYFUNCTION("GOOGLEFINANCE($A$3,P2)"),1.37) -> 1.37 | Q3: =IFERROR(__xludf.DUMMYFUNCTION("GOOGLEFINANCE($A$3,Q2)"),0.35) -> 0.35 | R3: =IFERROR(__xludf.DUMMYFUNCTION("GOOGLEFINANCE($A$3,R2)"),1.74) -> 1.74 | S3: =IFERROR(__xludf.DUMMYFUNCTION("GOOGLEFINANCE($A$3,S2)"),78.66) -> 78.66 | T3: =IFERROR(__xludf.DUMMYFUNCTION("GOOGLEFINANCE($A$3,T2)"),4.302482E9) -> 4302482000 | U3: =IFERROR(__xludf.DUMMYFUNCTION("GOOGLEFINANCE($A$3,U2)"),"USD") -> USD
A4: MSFT | B4: =IFERROR(__xludf.DUMMYFUNCTION("GOOGLEFINANCE($A$4,B2)"),"Microsoft Corp") -> Microsoft Corp | C4: =IFERROR(__xludf.DUMMYFUNCTION("GOOGLEFINANCE($A$4,C2)"),407.77) -> 407.77 | D4: =IFERROR(__xludf.DUMMYFUNCTION("GOOGLEFINANCE($A$4,D2)"),414.48) -> 414.48 | E4: =IFERROR(__xludf.DUMMYFUNCTION("GOOGLEFINANCE($A$4,E2)"),415.5) -> 415.5 | F4: =IFERROR(__xludf.DUMMYFUNCTION("GOOGLEFINANCE($A$4,F2)"),406.64) -> 406.64 | G4: =IFERROR(__xludf.DUMMYFUNCTION("GOOGLEFINANCE($A$4,G2)"),3.8594221E7) -> 38594221 | H4: =IFERROR(__xludf.DUMMYFUNCTION("GOOGLEFINANCE($A$4,H2)"),3.029092858338E12) -> 3029092858338 | I4: =IFERROR(__xludf.DUMMYFUNCTION("GOOGLEFINANCE($A$4,I2)"),46154.66667824074) -> 46154.667 | J4: =IFERROR(__xludf.DUMMYFUNCTION("GOOGLEFINANCE($A$4,J2)"),0.0) -> 0 | K4: =IFERROR(__xludf.DUMMYFUNCTION("GOOGLEFINANCE($A$4,K2)"),3.4199008E7) -> 34199008 | L4: =IFERROR(__xludf.DUMMYFUNCTION("GOOGLEFINANCE($A$4,L2)"),24.29) -> 24.29 | M4: =IFERROR(__xludf.DUMMYFUNCTION("GOOGLEFINANCE($A$4,M2)"),16.79) -> 16.79 | N4: =IFERROR(__xludf.DUMMYFUNCTION("GOOGLEFINANCE($A$4,N2)"),555.45) -> 555.45 | O4: =IFERROR(__xludf.DUMMYFUNCTION("GOOGLEFINANCE($A$4,O2)"),356.28) -> 356.28 | P4: =IFERROR(__xludf.DUMMYFUNCTION("GOOGLEFINANCE($A$4,P2)"),-4.89) -> -4.89 | Q4: =IFERROR(__xludf.DUMMYFUNCTION("GOOGLEFINANCE($A$4,Q2)"),1.1) -> 1.1 | R4: =IFERROR(__xludf.DUMMYFUNCTION("GOOGLEFINANCE($A$4,R2)"),-1.18) -> -1.18 | S4: =IFERROR(__xludf.DUMMYFUNCTION("GOOGLEFINANCE($A$4,S2)"),412.66) -> 412.66 | T4: =IFERROR(__xludf.DUMMYFUNCTION("GOOGLEFINANCE($A$4,T2)"),7.428435E9) -> 7428435000 | U4: =IFERROR(__xludf.DUMMYFUNCTION("GOOGLEFINANCE($A$4,U2)"),"USD") -> USD
A5: TSLA | B5: =IFERROR(__xludf.DUMMYFUNCTION("GOOGLEFINANCE($A$5,B2)"),"Tesla Inc") -> Tesla Inc | C5: =IFERROR(__xludf.DUMMYFUNCTION("GOOGLEFINANCE($A$5,C2)"),433.45) -> 433.45 | D5: =IFERROR(__xludf.DUMMYFUNCTION("GOOGLEFINANCE($A$5,D2)"),441.41) -> 441.41 | E5: =IFERROR(__xludf.DUMMYFUNCTION("GOOGLEFINANCE($A$5,E2)"),447.8) -> 447.8 | F5: =IFERROR(__xludf.DUMMYFUNCTION("GOOGLEFINANCE($A$5,F2)"),422.26) -> 422.26 | G5: =IFERROR(__xludf.DUMMYFUNCTION("GOOGLEFINANCE($A$5,G2)"),6.0569303E7) -> 60569303 | H5: =IFERROR(__xludf.DUMMYFUNCTION("GOOGLEFINANCE($A$5,H2)"),1.35820260975E12) -> 1358202609750 | I5: =IFERROR(__xludf.DUMMYFUNCTION("GOOGLEFINANCE($A$5,I2)"),46154.66666666667) -> 46154.667 | J5: =IFERROR(__xludf.DUMMYFUNCTION("GOOGLEFINANCE($A$5,J2)"),0.0) -> 0 | K5: =IFERROR(__xludf.DUMMYFUNCTION("GOOGLEFINANCE($A$5,K2)"),6.6093648E7) -> 66093648 | L5: =IFERROR(__xludf.DUMMYFUNCTION("GOOGLEFINANCE($A$5,L2)"),396.08) -> 396.08 | M5: =IFERROR(__xludf.DUMMYFUNCTION("GOOGLEFINANCE($A$5,M2)"),1.09) -> 1.09 | N5: =IFERROR(__xludf.DUMMYFUNCTION("GOOGLEFINANCE($A$5,N2)"),498.82) -> 498.82 | O5: =IFERROR(__xludf.DUMMYFUNCTION("GOOGLEFINANCE($A$5,O2)"),273.21) -> 273.21 | P5: =IFERROR(__xludf.DUMMYFUNCTION("GOOGLEFINANCE($A$5,P2)"),-11.63) -> -11.63 | Q5: =IFERROR(__xludf.DUMMYFUNCTION("GOOGLEFINANCE($A$5,Q2)"),1.79) -> 1.79 | R5: =IFERROR(__xludf.DUMMYFUNCTION("GOOGLEFINANCE($A$5,R2)"),-2.61) -> -2.61 | S5: =IFERROR(__xludf.DUMMYFUNCTION("GOOGLEFINANCE($A$5,S2)"),445.08) -> 445.08 | T5: =IFERROR(__xludf.DUMMYFUNCTION("GOOGLEFINANCE($A$5,T2)"),3.755724E9) -> 3755724000 | U5: =IFERROR(__xludf.DUMMYFUNCTION("GOOGLEFINANCE($A$5,U2)"),"USD") -> USD
A6: AAPL | B6: =IFERROR(__xludf.DUMMYFUNCTION("GOOGLEFINANCE($A$6,B2)"),"Apple Inc") -> Apple Inc | C6: =IFERROR(__xludf.DUMMYFUNCTION("GOOGLEFINANCE($A$6,C2)"),294.8) -> 294.8 | D6: =IFERROR(__xludf.DUMMYFUNCTION("GOOGLEFINANCE($A$6,D2)"),292.56) -> 292.56 | E6: =IFERROR(__xludf.DUMMYFUNCTION("GOOGLEFINANCE($A$6,E2)"),295.27) -> 295.27 | F6: =IFERROR(__xludf.DUMMYFUNCTION("GOOGLEFINANCE($A$6,F2)"),292.56) -> 292.56 | G6: =IFERROR(__xludf.DUMMYFUNCTION("GOOGLEFINANCE($A$6,G2)"),4.5748129E7) -> 45748129 | H6: =IFERROR(__xludf.DUMMYFUNCTION("GOOGLEFINANCE($A$6,H2)"),4.329830600711E12) -> 4329830600711 | I6: =IFERROR(__xludf.DUMMYFUNCTION("GOOGLEFINANCE($A$6,I2)"),46154.66667824074) -> 46154.667 | J6: =IFERROR(__xludf.DUMMYFUNCTION("GOOGLEFINANCE($A$6,J2)"),0.0) -> 0 | K6: =IFERROR(__xludf.DUMMYFUNCTION("GOOGLEFINANCE($A$6,K2)"),4.5699292E7) -> 45699292 | L6: =IFERROR(__xludf.DUMMYFUNCTION("GOOGLEFINANCE($A$6,L2)"),35.66) -> 35.66 | M6: =IFERROR(__xludf.DUMMYFUNCTION("GOOGLEFINANCE($A$6,M2)"),8.27) -> 8.27 | N6: =IFERROR(__xludf.DUMMYFUNCTION("GOOGLEFINANCE($A$6,N2)"),295.27) -> 295.27 | O6: =IFERROR(__xludf.DUMMYFUNCTION("GOOGLEFINANCE($A$6,O2)"),193.46) -> 193.46 | P6: =IFERROR(__xludf.DUMMYFUNCTION("GOOGLEFINANCE($A$6,P2)"),2.12) -> 2.12 | Q6: =IFERROR(__xludf.DUMMYFUNCTION("GOOGLEFINANCE($A$6,Q2)"),1.06) -> 1.06 | R6: =IFERROR(__xludf.DUMMYFUNCTION("GOOGLEFINANCE($A$6,R2)"),0.72) -> 0.72 | S6: =IFERROR(__xludf.DUMMYFUNCTION("GOOGLEFINANCE($A$6,S2)"),292.68) -> 292.68 | T6: =IFERROR(__xludf.DUMMYFUNCTION("GOOGLEFINANCE($A$6,T2)"),1.468736E10) -> 14687360000 | U6: =IFERROR(__xludf.DUMMYFUNCTION("GOOGLEFINANCE($A$6,U2)"),"USD") -> USD

Sheet PrecoHistorico
A1: Valor Normal | F1: Valor normalizado
A2: Data | B2: =Dados!A2 -> Coca-Cola Co | C2: =Dados!C2 -> Microsoft Corp | D2: =Dados!E2 -> Tesla Inc | E2: =Dados!G2 -> Apple Inc | F2: Coca-Cola Co | G2: Microsoft Corp | H2: Tesla Inc | I2: Apple Inc
A3: =Dados!A5 -> 43832.667 | B3: =Dados!B5 -> 54.99 | C3: =Dados!D5 -> 160.62 | D3: =Dados!F5 -> 28.68 | E3: =Dados!H5 -> 75.09 | F3: =STANDARDIZE(B3,$L$7,$L$8) -> 0.60837696 | G3: =STANDARDIZE(C3,$L$7,$L$8) -> 4.295288 | H3: =STANDARDIZE(D3,$L$7,$L$8) -> -0.30994764 | I3: =STANDARDIZE(E3,$L$7,$L$8) -> 1.3099476
A4: =Dados!A6 -> 43833.667 | B4: =Dados!B6 -> 54.69 | C4: =Dados!D6 -> 158.62 | D4: =Dados!F6 -> 29.53 | E4: =Dados!H6 -> 74.36 | F4: =STANDARDIZE(B4,$L$7,$L$8) -> 0.59790576 | G4: =STANDARDIZE(C4,$L$7,$L$8) -> 4.2254799 | H4: =STANDARDIZE(D4,$L$7,$L$8) -> -0.28027923 | I4: =STANDARDIZE(E4,$L$7,$L$8) -> 1.2844677
A5: =Dados!A7 -> 43836.667 | B5: =Dados!B7 -> 54.67 | C5: =Dados!D7 -> 159.03 | D5: =Dados!F7 -> 30.1 | E5: =Dados!H7 -> 74.95 | F5: =STANDARDIZE(B5,$L$7,$L$8) -> 0.59720768 | G5: =STANDARDIZE(C5,$L$7,$L$8) -> 4.2397906 | H5: =STANDARDIZE(D5,$L$7,$L$8) -> -0.26038394 | I5: =STANDARDIZE(E5,$L$7,$L$8) -> 1.3050611
A6: =Dados!A8 -> 43837.667 | B6: =Dados!B8 -> 54.25 | C6: =Dados!D8 -> 157.58 | D6: =Dados!F8 -> 31.27 | E6: =Dados!H8 -> 74.6 | F6: =STANDARDIZE(B6,$L$7,$L$8) -> 0.58254799 | G6: =STANDARDIZE(C6,$L$7,$L$8) -> 4.1891798 | H6: =STANDARDIZE(D6,$L$7,$L$8) -> -0.21954625 | I6: =STANDARDIZE(E6,$L$7,$L$8) -> 1.2928447 | K6: Maximo | L6: =MAX(B:B) -> 66.21
A7: =Dados!A9 -> 43838.667 | B7: =Dados!B9 -> 54.35 | C7: =Dados!D9 -> 160.09 | D7: =Dados!F9 -> 32.81 | E7: =Dados!H9 -> 75.8 | F7: =STANDARDIZE(B7,$L$7,$L$8) -> 0.58603839 | G7: =STANDARDIZE(C7,$L$7,$L$8) -> 4.2767888 | H7: =STANDARDIZE(D7,$L$7,$L$8) -> -0.16579407 | I7: =STANDARDIZE(E7,$L$7,$L$8) -> 1.3347295 | K7: Minimo | L7: =MIN(B:B) -> 37.56
A8: =Dados!A10 -> 43839.667 | B8: =Dados!B10 -> 55.34 | C8: =Dados!D10 -> 162.09 | D8: =Dados!F10 -> 32.09 | E8: =Dados!H10 -> 77.41 | F8: =STANDARDIZE(B8,$L$7,$L$8) -> 0.62059337 | G8: =STANDARDIZE(C8,$L$7,$L$8) -> 4.3465969 | H8: =STANDARDIZE(D8,$L$7,$L$8) -> -0.19092496 | I8: =STANDARDIZE(E8,$L$7,$L$8) -> 1.390925 | K8: Intervalo | L8: =L6-L7 -> 28.65
A9: =Dados!A11 -> 43840.667 | B9: =Dados!B11 -> 55.53 | C9: =Dados!D11 -> 161.34 | D9: =Dados!F11 -> 31.88 | E9: =Dados!H11 -> 77.58 | F9: =STANDARDIZE(B9,$L$7,$L$8) -> 0.62722513 | G9: =STANDARDIZE(C9,$L$7,$L$8) -> 4.3204188 | H9: =STANDARDIZE(D9,$L$7,$L$8) -> -0.1982548 | I9: =STANDARDIZE(E9,$L$7,$L$8) -> 1.3968586
A10: =Dados!A12 -> 43843.667 | B10: =Dados!B12 -> 56.13 | C10: =Dados!D12 -> 163.28 | D10: =Dados!F12 -> 34.99 | E10: =Dados!H12 -> 79.24 | F10: =STANDARDIZE(B10,$L$7,$L$8) -> 0.64816754 | G10: =STANDARDIZE(C10,$L$7,$L$8) -> 4.3881326 | H10: =STANDARDIZE(D10,$L$7,$L$8) -> -0.089703316 | I10: =STANDARDIZE(E10,$L$7,$L$8) -> 1.4547993
A11: =Dados!A13 -> 43844.667 | B11: =Dados!B13 -> 56 | C11: =Dados!D13 -> 162.13 | D11: =Dados!F13 -> 35.86 | E11: =Dados!H13 -> 78.17 | F11: =STANDARDIZE(B11,$L$7,$L$8) -> 0.64363002 | G11: =STANDARDIZE(C11,$L$7,$L$8) -> 4.347993 | H11: =STANDARDIZE(D11,$L$7,$L$8) -> -0.059336824 | I11: =STANDARDIZE(E11,$L$7,$L$8) -> 1.417452
A12: =Dados!A14 -> 43845.667 | B12: =Dados!B14 -> 56.7 | C12: =Dados!D14 -> 163.18 | D12: =Dados!F14 -> 34.57 | E12: =Dados!H14 -> 77.83 | F12: =STANDARDIZE(B12,$L$7,$L$8) -> 0.66806283 | G12: =STANDARDIZE(C12,$L$7,$L$8) -> 4.3846422 | H12: =STANDARDIZE(D12,$L$7,$L$8) -> -0.104363 | I12: =STANDARDIZE(E12,$L$7,$L$8) -> 1.4055846
A13: =Dados!A15 -> 43846.667 | B13: =Dados!B15 -> 56.82 | C13: =Dados!D15 -> 166.17 | D13: =Dados!F15 -> 34.23 | E13: =Dados!H15 -> 78.81 | F13: =STANDARDIZE(B13,$L$7,$L$8) -> 0.67225131 | G13: =STANDARDIZE(C13,$L$7,$L$8) -> 4.4890052 | H13: =STANDARDIZE(D13,$L$7,$L$8) -> -0.11623037 | I13: =STANDARDIZE(E13,$L$7,$L$8) -> 1.4397906
A14: =Dados!A16 -> 43847.667 | B14: =Dados!B16 -> 56.94 | C14: =Dados!D16 -> 167.1 | D14: =Dados!F16 -> 34.03 | E14: =Dados!H16 -> 79.68 | F14: =STANDARDIZE(B14,$L$7,$L$8) -> 0.67643979 | G14: =STANDARDIZE(C14,$L$7,$L$8) -> 4.521466 | H14: =STANDARDIZE(D14,$L$7,$L$8) -> -0.12321117 | I14: =STANDARDIZE(E14,$L$7,$L$8) -> 1.4701571
A15: =Dados!A17 -> 43851.667 | B15: =Dados!B17 -> 57.17 | C15: =Dados!D17 -> 166.5 | D15: =Dados!F17 -> 36.48 | E15: =Dados!H17 -> 79.14 | F15: =STANDARDIZE(B15,$L$7,$L$8) -> 0.68446771 | G15: =STANDARDIZE(C15,$L$7,$L$8) -> 4.5005236 | H15: =STANDARDIZE(D15,$L$7,$L$8) -> -0.037696335 | I15: =STANDARDIZE(E15,$L$7,$L$8) -> 1.4513089
A16: =Dados!A18 -> 43852.667 | B16: =Dados!B18 -> 57.61 | C16: =Dados!D18 -> 165.7 | D16: =Dados!F18 -> 37.97 | E16: =Dados!H18 -> 79.43 | F16: =STANDARDIZE(B16,$L$7,$L$8) -> 0.69982548 | G16: =STANDARDIZE(C16,$L$7,$L$8) -> 4.4726003 | H16: =STANDARDIZE(D16,$L$7,$L$8) -> 0.014310646 | I16: =STANDARDIZE(E16,$L$7,$L$8) -> 1.4614311
A17: =Dados!A19 -> 43853.667 | B17: =Dados!B19 -> 57.83 | C17: =Dados!D19 -> 166.72 | D17: =Dados!F19 -> 38.15 | E17: =Dados!H19 -> 79.81 | F17: =STANDARDIZE(B17,$L$7,$L$8) -> 0.70750436 | G17: =STANDARDIZE(C17,$L$7,$L$8) -> 4.5082024 | H17: =STANDARDIZE(D17,$L$7,$L$8) -> 0.020593368 | I17: =STANDARDIZE(E17,$L$7,$L$8) -> 1.4746946
A18: =Dados!A20 -> 43854.667 | B18: =Dados!B20 -> 57.68 | C18: =Dados!D20 -> 165.04 | D18: =Dados!F20 -> 37.65 | E18: =Dados!H20 -> 79.58 | F18: =STANDARDIZE(B18,$L$7,$L$8) -> 0.70226876 | G18: =STANDARDIZE(C18,$L$7,$L$8) -> 4.4495637 | H18: =STANDARDIZE(D18,$L$7,$L$8) -> 0.0031413613 | I18: =STANDARDIZE(E18,$L$7,$L$8) -> 1.4666667
A19: =Dados!A21 -> 43857.667 | B19: =Dados!B21 -> 57.48 | C19: =Dados!D21 -> 162.28 | D19: =Dados!F21 -> 37.2 | E19: =Dados!H21 -> 77.24 | F19: =STANDARDIZE(B19,$L$7,$L$8) -> 0.69528796 | G19: =STANDARDIZE(C19,$L$7,$L$8) -> 4.3532286 | H19: =STANDARDIZE(D19,$L$7,$L$8) -> -0.012565445 | I19: =STANDARDIZE(E19,$L$7,$L$8) -> 1.3849913
A20: =Dados!A22 -> 43858.667 | B20: =Dados!B22 -> 57.01 | C20: =Dados!D22 -> 165.46 | D20: =Dados!F22 -> 37.79 | E20: =Dados!H22 -> 79.42 | F20: =STANDARDIZE(B20,$L$7,$L$8) -> 0.67888307 | G20: =STANDARDIZE(C20,$L$7,$L$8) -> 4.4642234 | H20: =STANDARDIZE(D20,$L$7,$L$8) -> 0.0080279232 | I20: =STANDARDIZE(E20,$L$7,$L$8) -> 1.461082
... A758: =Dados!A760 -> 44925.667 | B758: =Dados!B760 -> 63.61 | C758: =Dados!D760 -> 239.82 | D758: =Dados!F760 -> 123.18 | E758: =Dados!H760 -> 129.93 | F758: =STANDARDIZE(B758,$L$7,$L$8) -> 0.90924956 | G758: =STANDARDIZE(C758,$L$7,$L$8) -> 7.0596859 | H758: =STANDARDIZE(D758,$L$7,$L$8) -> 2.9884817 | I758: =STANDARDIZE(E758,$L$7,$L$8) -> 3.2240838
A759: =Dados!A761
A760: =Dados!A762
A761: =Dados!A763
